Workbook

Sheet pvs_eval
A1: Document ID | B1: Organization ID | C1: Document Link | D1: Note Type Class | E1: Reader Specialty | F1: Model 1 Generated Summary | G1: Model 2 Generated Summary | H1: Model 3 Generated Summary | I1: Hallucination - Fabrication | J1: Hallucination findings | L1: Halluciantion - Inference | M1: Inference Breakdown | N1: Inference findings | P1: Pertinent Omission | Q1: Omission findings | R1: Omission Severity | T1: Extraneous Information | U1: Extraneous Information findings | V1: Extraneous Information Severity | X1: Flow | Y1: Flow findings | AB1: Comments: One liner enhancement | AC1: Comments: visit summary
A2: 35193739052 | B2: 650b99b2-81d4-4801-bac5-fdf999d25556 | C2: suki_650b99b2-81d4-4801-bac5-fdf999d25556_patients_1758678_35193739052.pdf | D2: POST_OPERATIVE_REPORT | E2: Internal Medicine | F2: Anesthesia postoperative evaluation following surgery. Patient remains intubated and sedated with stable vital signs and adequate hydration. No perioperative complications were reported. Transferred to the ICU for ongoing ventilatory support and close clinical monitoring. | G2: Postoperative anesthesia evaluation shows the patient remains intubated and sedated with a patent airway. No perioperative events or complications occurred. Hemodynamics are stable with adequate pain control. The patient is transferred to the ICU for continued monitoring. | H2: Post-anesthesia evaluation after surgery: intubated/sedated with patent airway and adequate hydration. No nausea/vomiting, pain 0, and no perioperative events. Hemodynamically stable (BP 142/71, pulse 60, SpO2 99%); planned ICU care.
A3: 35451377528 | B3: 650b99b2-81d4-4801-bac5-fdf999d25556 | C3: suki_650b99b2-81d4-4801-bac5-fdf999d25556_patients_1853027_35451377528.pdf | D3: OPERATIVE_REPORT | E3: Internal Medicine | F3: Upper GI endoscopy performed for gastroesophageal reflux disease. Findings revealed a normal esophagus and duodenum with two sessile gastric fundus polyps. Polyps were resected via cold snare. Plan involves awaiting pathology results while continuing current medications and diet. | G3: Upper GI endoscopy for gastroesophageal reflux disease revealed a normal esophagus and duodenum. Two 4 mm sessile polyps in the gastric fundus were resected with a cold snare and retrieved. The plan is to await pathology results. | H3: EGD for GERD symptoms revealed normal esophagus and duodenum; two 4‑mm sessile gastric fundus polyps were cold-snare resected and retrieved without complications. Advised resume diet/meds, return to normal activities next day, and await pathology.
A4: 34981575364 | B4: 650b99b2-81d4-4801-bac5-fdf999d25556 | C4: suki_650b99b2-81d4-4801-bac5-fdf999d25556_patients_1990276_34981575364.pdf | D4: OFFICE_CLINIC_NOTE | E4: Internal Medicine | F4: Evaluation for third liver transplant due to ischemic cholangiopathy and celiac artery thrombosis. Notable findings include biliary obstruction and stage 3 chronic kidney disease. Plan involves an IR consult and high-volume blood product preparation. Normal echocardiogram noted. | G4: Anesthesia evaluation for a third liver transplant complicated by ischemic cholangiopathy and celiac artery thrombosis. The patient is highly deconditioned with a normal echocardiogram. Due to significant surgical complexity, ordered an IR consult and recommended preparing 20 PRBCs. | H4: Anesthesia evaluation for potential third liver transplant for ischemic cholangiopathy with celiac/portal vein thromboses and biliary obstruction. Markedly deconditioned; CKD3 with anemia/thrombocytopenia on apixaban. Echo normal EF with mild–moderate MR. Plan: prepare 20 units PRBC; IR consult.
A5: 35409948227 | B5: 650b99b2-81d4-4801-bac5-fdf999d25556 | C5: suki_650b99b2-81d4-4801-bac5-fdf999d25556_patients_2042341_35409948227.pdf | D5: DISCHARGE_SUMMARY | E5: Internal Medicine | F5: Hospitalization for chest pain, alcohol intoxication, and altered mental status. Managed acute gout flare with anakinra and encephalopathy via CIWA protocol. Restarted allopurinol after ruling out fracture and DVT. Discharge plan involves rheumatology, nephrology, and primary care follow-up. | G5: Admitted for chest pain, altered mental status, and alcohol intoxication, resolving with CIWA-guided therapy. Hospitalization complicated by a left arm gout flare requiring anakinra due to standard medication intolerances. Discharged on low-dose allopurinol with pending labs and multidisciplinary follow-up. | H5: Admitted after unresponsiveness with chest pain, alcohol intoxication, and altered mental status. Left wrist/hand gout flare; colchicine/NSAIDs/steroids not tolerated. Treated with CIWA benzodiazepines/thiamine, anakinra, and restarted allopurinol. Discharged with primary care, rheumatology, and nephrology follow-up and pending BMP/CBC/magnesium.
A6: 36033589720 | B6: 650b99b2-81d4-4801-bac5-fdf999d25556 | C6: suki_650b99b2-81d4-4801-bac5-fdf999d25556_patients_2070888_36033589720.pdf | D6: DISCHARGE_SUMMARY | E6: Internal Medicine | F6: Hospital discharge for left internal jugular vein thrombus associated with an indwelling port. Initiated apixaban for anticoagulation. Plan includes repeat CBC and oncology follow-up to discuss port management and therapeutic duration for metastatic breast cancer. | G6: Hospitalized for dyspnea, revealing a new port-associated left internal jugular vein thrombus in the setting of metastatic breast cancer. Initiated apixaban. Discharged with orders for a repeat CBC and oncology follow-up to determine port management and anticoagulation duration. | H6: Hospitalized for dyspnea; CTA ruled out pulmonary embolism but suggested left internal jugular thrombosis, nonocclusive on duplex, possibly port-related. Discharged on apixaban, bleeding precautions, repeat CBC in one week, follow up with PCP/oncology for port and anticoagulation duration.
A7: 35935671184 | B7: 650b99b2-81d4-4801-bac5-fdf999d25556 | C7: suki_650b99b2-81d4-4801-bac5-fdf999d25556_patients_2206314_35935671184.pdf | D7: POST_OPERATIVE_REPORT | E7: Internal Medicine | F7: Post-operative evaluation for left lower quadrant pain and vomiting following Roux-en-Y gastric bypass. CT angiography ruled out pulmonary embolism, bowel obstruction, and anastomotic leak. Findings include bilateral adrenal gland thickening. No acute imaging findings correlate with history. | G7: CT angiography evaluated left lower quadrant pain and vomiting after Roux-en-Y gastric bypass. The scan revealed no acute findings, pulmonary embolism, or bowel obstruction. Incidental bilateral adrenal gland thickening and mild coronary artery calcifications were noted. | H7: Post–gastric bypass patient evaluated for left lower quadrant pain and vomiting. CTA chest/abdomen/pelvis with IV contrast found no pulmonary embolism, bowel obstruction/inflammation, appendicitis, pneumatosis, free air/fluid, or hydronephrosis; mild coronary calcifications and bilateral adrenal thickening.
A8: 35878129290 | B8: 650b99b2-81d4-4801-bac5-fdf999d25556 | C8: suki_650b99b2-81d4-4801-bac5-fdf999d25556_patients_2647831_35878129290.pdf | D8: OFFICE_CLINIC_NOTE | E8: Internal Medicine | F8: Primary care follow-up for poorly controlled diabetes and BPH. Adjusted Jardiance frequency for hyperglycemia and medication non-adherence. Ordered A1c, lipids, and PSA to monitor Stage 3a CKD, hypercholesterolemia, and prostate symptoms. Administered flu vaccine; return in four months. | G8: Primary care visit for type 2 diabetes with hyperglycemia, pure hypercholesterolemia, and worsening Stage 3a CKD. Adjusted Jardiance to every other day for tolerability and refilled other chronic medications. Administered flu vaccine and provided extensive lifestyle counseling. | H8: Followup for uncontrolled T2DM with hypertriglyceridemia and stage 3a CKD. Counseled on diet and adherence; continued metformin and Rybelsus, restarted Jardiance every other day. Refilled losartan and simvastatin; ordered A1c, BMP, microalbumin, lipids; gave flu vaccine and advised COVID booster.
A9: 35187269729 | B9: 650b99b2-81d4-4801-bac5-fdf999d25556 | C9: suki_650b99b2-81d4-4801-bac5-fdf999d25556_patients_3629834_35187269729.pdf | D9: ED_NOTE | E9: Internal Medicine | F9: Emergency visit for chest pain, unspecified type, likely musculoskeletal in origin. Negative serial troponins, stable chest x-ray, and paced rhythm ruled out acute coronary syndrome. Discharged home with PRN acetaminophen and instructions to follow up with primary care. | G9: ED visit for reproducible left chest pain. Serial troponins, EKG, and chest x-ray were negative, ruling out acute coronary syndrome. Diagnosed with musculoskeletal chest wall pain. Discharged home with recommendations for acetaminophen and primary care follow-up. | H9: ED visit for left-sided chest pain after lifting; exam showed reproducible chest wall tenderness. ACS ruled out with paced EKG without ischemic changes, troponins negative, and normal chest X-ray. Treated with acetaminophen; discharged with PCP follow-up and return precautions.
A10: 33722621549 | B10: 650b99b2-81d4-4801-bac5-fdf999d25556 | C10: suki_650b99b2-81d4-4801-bac5-fdf999d25556_patients_5468853_33722621549.pdf | D10: OFFICE_CLINIC_NOTE | E10: Internal Medicine | F10: Urgent care visit for worsening right wrist pain following travel. Imaging confirmed 1st CMC and triscaphe osteoarthritis without acute fracture. Prescribed topical diclofenac and referred to orthopedics. Advised joint rest and follow-up with primary care for chronic management. | G10: Urgent care visit for progressive right wrist pain after rolling luggage. X-rays revealed mild osteoarthritis without acute fracture. Assessed with wrist pain, likely tendinopathy or arthritis. Prescribed topical diclofenac, advised rest, and referred to orthopedics for further evaluation. | H10: Seen for 2 months progressive right radial wrist pain after prolonged suitcase rolling with thumb weakness. Exam tender without swelling. Wrist X-ray: no fracture, osteopenia, mild 1st CMC/triscaphe osteoarthritis. Started topical diclofenac, advised rest/gentle ROM, orthopedic referral.
A11: 34043945278 | B11: 650b99b2-81d4-4801-bac5-fdf999d25556 | C11: suki_650b99b2-81d4-4801-bac5-fdf999d25556_patients_5468853_34043945278.pdf | D11: OFFICE_CLINIC_NOTE | E11: Internal Medicine | F11: Rheumatology follow-up for undifferentiated connective tissue disease and dyspnea. Increased amlodipine for worsening Raynaud's. Ordered comprehensive labs including dsDNA, complement, and hydroxychloroquine levels. Reiterated importance of PFTs and recommended pulmonology, ophthalmology, and diabetic evaluations. | G11: Rheumatology visit for UCTD with ongoing dyspnea and worsened Raynaud's. Increased amlodipine. Strongly urged PFTs and pulmonology evaluation to assess dyspnea for pulmonary arterial hypertension. Ordered comprehensive autoimmune monitoring labs and an HbA1c. | H11: Follow-up for UCTD with centromere positivity, dyspnea, worsening Raynaud, and prediabetes. CT stable bronchiolitis/bronchiectasis; echo RVSP normal but PAH risk—urged PFTs and pulmonary follow-up, no additional immunosuppression. Increased amlodipine, continued hydroxychloroquine with eye exam, ordered labs and A1c.
A12: 35621314683 | B12: 650b99b2-81d4-4801-bac5-fdf999d25556 | C12: suki_650b99b2-81d4-4801-bac5-fdf999d25556_patients_5919647_35621314683.pdf | D12: HISTORY_AND_PHYSICAL_NOTE | E12: Internal Medicine | F12: Gastroenterology visit for screening colonoscopy and constipation with possible rectal prolapse. Significant history includes tubular adenomas and family history of colon cancer. Scheduled colonoscopy and ordered Suprep bowel prep. Recommended continuing daily Miralax and adding fiber. | G12: Gastroenterology visit for colonoscopy screening given a history of tubular adenomas and maternal colon cancer. Scheduled the procedure and ordered Suprep bowel kit. Advised continuing daily Miralax and adding a fiber supplement to manage straining and constipation. | H12: GI visit for colonoscopy screening after prior poor prep, tubular adenomas, and maternal colon cancer; constipation and hemorrhoids with vaginal bulge under urogyne evaluation. Colonoscopy scheduled; Suprep prescribed, risks reviewed, confirmed no anticoagulants or GLP1. Continue Miralax and add fiber.
A13: 34504784857 | B13: 650b99b2-81d4-4801-bac5-fdf999d25556 | C13: suki_650b99b2-81d4-4801-bac5-fdf999d25556_patients_8374797_34504784857.pdf | D13: DISCHARGE_SUMMARY | E13: Internal Medicine | F13: Hospitalization for abdominal pain and diarrhea. Diagnosed with colitis and bilateral obstructive ureteral calculi. Underwent cystoscopy with bilateral stent placement. Discharged on cefuroxime, metronidazole, tamsulosin, and pyridium. Plan includes urology follow-up and evaluation of a potential pelvic mass. | G13: Admission for abdominal pain and diarrhea. Discharge diagnoses: 1. Bilateral obstructive ureteral calculi, 2. Colitis. Treated with cystoscopy and bilateral stent placement. Discharged on cefuroxime, metronidazole, tamsulosin, and pyridium with planned outpatient urology follow-up. | H13: Hospitalized for right-sided abdominal pain with diarrhea/vomiting. CT showed bilateral obstructing ureteral calculi and colitis; incidental uterine mass. Underwent cystoscopy with bilateral ureteral stents; treated with cefuroxime/metronidazole, discharged stable on tamsulosin/pyridium, follow up urology.
... A101: 6392371952 | B101: 7312933c-5982-4313-8530-433214730c33 | C101: suki_7312933c-5982-4313-8530-433214730c33_patients_7256517_6392371952.pdf | D101: OPERATIVE_REPORT | E101: Internal Medicine | F101: T10 to pelvis posterior instrumented fusion and bilateral SI joint fusion performed for degenerative scoliosis and spondylosis. Spinal cord stimulator removed. Intraoperative course notable for 1200 mL blood loss and four-unit PRBC transfusion. Patient stable postoperatively. | G101: Operative report for degenerative scoliosis and L2-S1 spondylosis with foraminal stenosis. Underwent T10-to-pelvis posterior instrumented fusion, L2-L5 osteotomies, bilateral SI joint fusion, and spinal cord stimulator removal. Blood loss was 1,200 mL with 4 units PRBCs given. No complications. | H101: For degenerative scoliosis with severe L2–S1 spondylosis/foraminal stenosis, underwent T10–pelvis posterior instrumented fusion, L2–5 osteotomies with laminectomy/foraminotomies, bilateral SI joint fusion, and cord stimulator explant. EBL 1.2 L; 4 units PRBC; no complications; extubated stable.

Sheet metrics
A1: Metrics | B1: Acceptance Rate | C1: Error Rate | E1: Hallucination - Fabrication | F1: Hallucination - Inference | G1: Inference Breakdown | H1: Pertinent Omission | I1: Extraneous Information | J1: Flow
A2: Hallucination - Fabriaction | B2: =AVERAGE(E:E) -> #DIV/0! | C2: =(1-B2) -> #DIV/0! | E2: =IF(ISBLANK(pvs_eval!I2), "", IF(pvs_eval!I2 = "No hallucination", 1, 0)) | F2: =IF(ISBLANK(pvs_eval!L2), "", IF(pvs_eval!L2 = "No clinical inference", 1, 0)) | G2: =IF(ISBLANK(pvs_eval!M2), "", IF(pvs_eval!M2 = "Unsafe, Non-Deducible Inference", 0, 1)) | H2: =IF(ISBLANK(pvs_eval!P2), "", IF(pvs_eval!P2 = "No omission", 1, 0)) | I2: =IF(ISBLANK(pvs_eval!T2), "", IF(pvs_eval!T2 = "No extraneous information", 1, 0)) | J2: =IF(ISBLANK(pvs_eval!X2), "", IF(pvs_eval!X2 = "No flow issues", 1, 0))
A3: Hallucination - Inference | B3: =AVERAGE(F:F) -> #DIV/0! | C3: =(1-B3) -> #DIV/0! | E3: =IF(ISBLANK(pvs_eval!I3), "", IF(pvs_eval!I3 = "No hallucination", 1, 0)) | F3: =IF(ISBLANK(pvs_eval!L3), "", IF(pvs_eval!L3 = "No clinical inference", 1, 0)) | G3: =IF(ISBLANK(pvs_eval!M3), "", IF(pvs_eval!M3 = "Unsafe, Non-Deducible Inference", 0, 1)) | H3: =IF(ISBLANK(pvs_eval!P3), "", IF(pvs_eval!P3 = "No omission", 1, 0)) | I3: =IF(ISBLANK(pvs_eval!T3), "", IF(pvs_eval!T3 = "No extraneous information", 1, 0)) | J3: =IF(ISBLANK(pvs_eval!X3), "", IF(pvs_eval!X3 = "No flow issues", 1, 0))
A4: Inference Breakdown | B4: =AVERAGE(G:G) -> #DIV/0! | C4: =(1-B4) -> #DIV/0! | E4: =IF(ISBLANK(pvs_eval!I5), "", IF(pvs_eval!I5 = "No hallucination", 1, 0)) | F4: =IF(ISBLANK(pvs_eval!L5), "", IF(pvs_eval!L5 = "No clinical inference", 1, 0)) | G4: =IF(ISBLANK(pvs_eval!M5), "", IF(pvs_eval!M5 = "Unsafe, Non-Deducible Inference", 0, 1)) | H4: =IF(ISBLANK(pvs_eval!P5), "", IF(pvs_eval!P5 = "No omission", 1, 0)) | I4: =IF(ISBLANK(pvs_eval!T5), "", IF(pvs_eval!T5 = "No extraneous information", 1, 0)) | J4: =IF(ISBLANK(pvs_eval!X5), "", IF(pvs_eval!X5 = "No flow issues", 1, 0))
A5: Pertinent Omission | B5: =AVERAGE(H:H) -> #DIV/0! | C5: =(1-B5) -> #DIV/0! | E5: =IF(ISBLANK(pvs_eval!I6), "", IF(pvs_eval!I6 = "No hallucination", 1, 0)) | F5: =IF(ISBLANK(pvs_eval!L6), "", IF(pvs_eval!L6 = "No clinical inference", 1, 0)) | G5: =IF(ISBLANK(pvs_eval!M6), "", IF(pvs_eval!M6 = "Unsafe, Non-Deducible Inference", 0, 1)) | H5: =IF(ISBLANK(pvs_eval!P6), "", IF(pvs_eval!P6 = "No omission", 1, 0)) | I5: =IF(ISBLANK(pvs_eval!T6), "", IF(pvs_eval!T6 = "No extraneous information", 1, 0)) | J5: =IF(ISBLANK(pvs_eval!X6), "", IF(pvs_eval!X6 = "No flow issues", 1, 0))
A6: Extranous Information | B6: =AVERAGE(I:I) -> #DIV/0! | C6: =(1-B6) -> #DIV/0! | E6: =IF(ISBLANK(pvs_eval!I7), "", IF(pvs_eval!I7 = "No hallucination", 1, 0)) | F6: =IF(ISBLANK(pvs_eval!L7), "", IF(pvs_eval!L7 = "No clinical inference", 1, 0)) | G6: =IF(ISBLANK(pvs_eval!M7), "", IF(pvs_eval!M7 = "Unsafe, Non-Deducible Inference", 0, 1)) | H6: =IF(ISBLANK(pvs_eval!P7), "", IF(pvs_eval!P7 = "No omission", 1, 0)) | I6: =IF(ISBLANK(pvs_eval!T7), "", IF(pvs_eval!T7 = "No extraneous information", 1, 0)) | J6: =IF(ISBLANK(pvs_eval!X7), "", IF(pvs_eval!X7 = "No flow issues", 1, 0))
A7: Flow | B7: =AVERAGE(J:J) -> #DIV/0! | C7: =(1-B7) -> #DIV/0! | E7: =IF(ISBLANK(pvs_eval!I8), "", IF(pvs_eval!I8 = "No hallucination", 1, 0)) | F7: =IF(ISBLANK(pvs_eval!L8), "", IF(pvs_eval!L8 = "No clinical inference", 1, 0)) | G7: =IF(ISBLANK(pvs_eval!M8), "", IF(pvs_eval!M8 = "Unsafe, Non-Deducible Inference", 0, 1)) | H7: =IF(ISBLANK(pvs_eval!P8), "", IF(pvs_eval!P8 = "No omission", 1, 0)) | I7: =IF(ISBLANK(pvs_eval!T8), "", IF(pvs_eval!T8 = "No extraneous information", 1, 0)) | J7: =IF(ISBLANK(pvs_eval!X8), "", IF(pvs_eval!X8 = "No flow issues", 1, 0))
E8: =IF(ISBLANK(pvs_eval!I10), "", IF(pvs_eval!I10 = "No hallucination", 1, 0)) | F8: =IF(ISBLANK(pvs_eval!L10), "", IF(pvs_eval!L10 = "No clinical inference", 1, 0)) | G8: =IF(ISBLANK(pvs_eval!M10), "", IF(pvs_eval!M10 = "Unsafe, Non-Deducible Inference", 0, 1)) | H8: =IF(ISBLANK(pvs_eval!P10), "", IF(pvs_eval!P10 = "No omission", 1, 0)) | I8: =IF(ISBLANK(pvs_eval!T10), "", IF(pvs_eval!T10 = "No extraneous information", 1, 0)) | J8: =IF(ISBLANK(pvs_eval!X10), "", IF(pvs_eval!X10 = "No flow issues", 1, 0))
A9: Total Completed | B9: =COUNT(E:E) -> 0 | E9: =IF(ISBLANK(pvs_eval!I11), "", IF(pvs_eval!I11 = "No hallucination", 1, 0)) | F9: =IF(ISBLANK(pvs_eval!L11), "", IF(pvs_eval!L11 = "No clinical inference", 1, 0)) | G9: =IF(ISBLANK(pvs_eval!M11), "", IF(pvs_eval!M11 = "Unsafe, Non-Deducible Inference", 0, 1)) | H9: =IF(ISBLANK(pvs_eval!P11), "", IF(pvs_eval!P11 = "No omission", 1, 0)) | I9: =IF(ISBLANK(pvs_eval!T11), "", IF(pvs_eval!T11 = "No extraneous information", 1, 0)) | J9: =IF(ISBLANK(pvs_eval!X11), "", IF(pvs_eval!X11 = "No flow issues", 1, 0))
E10: =IF(ISBLANK(pvs_eval!I12), "", IF(pvs_eval!I12 = "No hallucination", 1, 0)) | F10: =IF(ISBLANK(pvs_eval!L12), "", IF(pvs_eval!L12 = "No clinical inference", 1, 0)) | G10: =IF(ISBLANK(pvs_eval!M12), "", IF(pvs_eval!M12 = "Unsafe, Non-Deducible Inference", 0, 1)) | H10: =IF(ISBLANK(pvs_eval!P12), "", IF(pvs_eval!P12 = "No omission", 1, 0)) | I10: =IF(ISBLANK(pvs_eval!T12), "", IF(pvs_eval!T12 = "No extraneous information", 1, 0)) | J10: =IF(ISBLANK(pvs_eval!X12), "", IF(pvs_eval!X12 = "No flow issues", 1, 0))
E11: =IF(ISBLANK(pvs_eval!I13), "", IF(pvs_eval!I13 = "No hallucination", 1, 0)) | F11: =IF(ISBLANK(pvs_eval!L13), "", IF(pvs_eval!L13 = "No clinical inference", 1, 0)) | G11: =IF(ISBLANK(pvs_eval!M13), "", IF(pvs_eval!M13 = "Unsafe, Non-Deducible Inference", 0, 1)) | H11: =IF(ISBLANK(pvs_eval!P13), "", IF(pvs_eval!P13 = "No omission", 1, 0)) | I11: =IF(ISBLANK(pvs_eval!T13), "", IF(pvs_eval!T13 = "No extraneous information", 1, 0)) | J11: =IF(ISBLANK(pvs_eval!X13), "", IF(pvs_eval!X13 = "No flow issues", 1, 0))
E12: =IF(ISBLANK(pvs_eval!I15), "", IF(pvs_eval!I15 = "No hallucination", 1, 0)) | F12: =IF(ISBLANK(pvs_eval!L15), "", IF(pvs_eval!L15 = "No clinical inference", 1, 0)) | G12: =IF(ISBLANK(pvs_eval!M15), "", IF(pvs_eval!M15 = "Unsafe, Non-Deducible Inference", 0, 1)) | H12: =IF(ISBLANK(pvs_eval!P15), "", IF(pvs_eval!P15 = "No omission", 1, 0)) | I12: =IF(ISBLANK(pvs_eval!T15), "", IF(pvs_eval!T15 = "No extraneous information", 1, 0)) | J12: =IF(ISBLANK(pvs_eval!X15), "", IF(pvs_eval!X15 = "No flow issues", 1, 0))
E13: =IF(ISBLANK(pvs_eval!I16), "", IF(pvs_eval!I16 = "No hallucination", 1, 0)) | F13: =IF(ISBLANK(pvs_eval!L16), "", IF(pvs_eval!L16 = "No clinical inference", 1, 0)) | G13: =IF(ISBLANK(pvs_eval!M16), "", IF(pvs_eval!M16 = "Unsafe, Non-Deducible Inference", 0, 1)) | H13: =IF(ISBLANK(pvs_eval!P16), "", IF(pvs_eval!P16 = "No omission", 1, 0)) | I13: =IF(ISBLANK(pvs_eval!T16), "", IF(pvs_eval!T16 = "No extraneous information", 1, 0)) | J13: =IF(ISBLANK(pvs_eval!X16), "", IF(pvs_eval!X16 = "No flow issues", 1, 0))
E14: =IF(ISBLANK(pvs_eval!I17), "", IF(pvs_eval!I17 = "No hallucination", 1, 0)) | F14: =IF(ISBLANK(pvs_eval!L17), "", IF(pvs_eval!L17 = "No clinical inference", 1, 0)) | G14: =IF(ISBLANK(pvs_eval!M17), "", IF(pvs_eval!M17 = "Unsafe, Non-Deducible Inference", 0, 1)) | H14: =IF(ISBLANK(pvs_eval!P17), "", IF(pvs_eval!P17 = "No omission", 1, 0)) | I14: =IF(ISBLANK(pvs_eval!T17), "", IF(pvs_eval!T17 = "No extraneous information", 1, 0)) | J14: =IF(ISBLANK(pvs_eval!X17), "", IF(pvs_eval!X17 = "No flow issues", 1, 0))
E15: =IF(ISBLANK(pvs_eval!I18), "", IF(pvs_eval!I18 = "No hallucination", 1, 0)) | F15: =IF(ISBLANK(pvs_eval!L18), "", IF(pvs_eval!L18 = "No clinical inference", 1, 0)) | G15: =IF(ISBLANK(pvs_eval!M18), "", IF(pvs_eval!M18 = "Unsafe, Non-Deducible Inference", 0, 1)) | H15: =IF(ISBLANK(pvs_eval!P18), "", IF(pvs_eval!P18 = "No omission", 1, 0)) | I15: =IF(ISBLANK(pvs_eval!T18), "", IF(pvs_eval!T18 = "No extraneous information", 1, 0)) | J15: =IF(ISBLANK(pvs_eval!X18), "", IF(pvs_eval!X18 = "No flow issues", 1, 0))
E16: =IF(ISBLANK(pvs_eval!I20), "", IF(pvs_eval!I20 = "No hallucination", 1, 0)) | F16: =IF(ISBLANK(pvs_eval!L20), "", IF(pvs_eval!L20 = "No clinical inference", 1, 0)) | G16: =IF(ISBLANK(pvs_eval!M20), "", IF(pvs_eval!M20 = "Unsafe, Non-Deducible Inference", 0, 1)) | H16: =IF(ISBLANK(pvs_eval!P20), "", IF(pvs_eval!P20 = "No omission", 1, 0)) | I16: =IF(ISBLANK(pvs_eval!T20), "", IF(pvs_eval!T20 = "No extraneous information", 1, 0)) | J16: =IF(ISBLANK(pvs_eval!X20), "", IF(pvs_eval!X20 = "No flow issues", 1, 0))
E17: =IF(ISBLANK(pvs_eval!I21), "", IF(pvs_eval!I21 = "No hallucination", 1, 0)) | F17: =IF(ISBLANK(pvs_eval!L21), "", IF(pvs_eval!L21 = "No clinical inference", 1, 0)) | G17: =IF(ISBLANK(pvs_eval!M21), "", IF(pvs_eval!M21 = "Unsafe, Non-Deducible Inference", 0, 1)) | H17: =IF(ISBLANK(pvs_eval!P21), "", IF(pvs_eval!P21 = "No omission", 1, 0)) | I17: =IF(ISBLANK(pvs_eval!T21), "", IF(pvs_eval!T21 = "No extraneous information", 1, 0)) | J17: =IF(ISBLANK(pvs_eval!X21), "", IF(pvs_eval!X21 = "No flow issues", 1, 0))
E18: =IF(ISBLANK(pvs_eval!I22), "", IF(pvs_eval!I22 = "No hallucination", 1, 0)) | F18: =IF(ISBLANK(pvs_eval!L22), "", IF(pvs_eval!L22 = "No clinical inference", 1, 0)) | G18: =IF(ISBLANK(pvs_eval!M22), "", IF(pvs_eval!M22 = "Unsafe, Non-Deducible Inference", 0, 1)) | H18: =IF(ISBLANK(pvs_eval!P22), "", IF(pvs_eval!P22 = "No omission", 1, 0)) | I18: =IF(ISBLANK(pvs_eval!T22), "", IF(pvs_eval!T22 = "No extraneous information", 1, 0)) | J18: =IF(ISBLANK(pvs_eval!X22), "", IF(pvs_eval!X22 = "No flow issues", 1, 0))
E19: =IF(ISBLANK(pvs_eval!I23), "", IF(pvs_eval!I23 = "No hallucination", 1, 0)) | F19: =IF(ISBLANK(pvs_eval!L23), "", IF(pvs_eval!L23 = "No clinical inference", 1, 0)) | G19: =IF(ISBLANK(pvs_eval!M23), "", IF(pvs_eval!M23 = "Unsafe, Non-Deducible Inference", 0, 1)) | H19: =IF(ISBLANK(pvs_eval!P23), "", IF(pvs_eval!P23 = "No omission", 1, 0)) | I19: =IF(ISBLANK(pvs_eval!T23), "", IF(pvs_eval!T23 = "No extraneous information", 1, 0)) | J19: =IF(ISBLANK(pvs_eval!X23), "", IF(pvs_eval!X23 = "No flow issues", 1, 0))
E20: =IF(ISBLANK(pvs_eval!I25), "", IF(pvs_eval!I25 = "No hallucination", 1, 0)) | F20: =IF(ISBLANK(pvs_eval!L25), "", IF(pvs_eval!L25 = "No clinical inference", 1, 0)) | G20: =IF(ISBLANK(pvs_eval!M25), "", IF(pvs_eval!M25 = "Unsafe, Non-Deducible Inference", 0, 1)) | H20: =IF(ISBLANK(pvs_eval!P25), "", IF(pvs_eval!P25 = "No omission", 1, 0)) | I20: =IF(ISBLANK(pvs_eval!T25), "", IF(pvs_eval!T25 = "No extraneous information", 1, 0)) | J20: =IF(ISBLANK(pvs_eval!X25), "", IF(pvs_eval!X25 = "No flow issues", 1, 0))
E21: =IF(ISBLANK(pvs_eval!I26), "", IF(pvs_eval!I26 = "No hallucination", 1, 0)) | F21: =IF(ISBLANK(pvs_eval!L26), "", IF(pvs_eval!L26 = "No clinical inference", 1, 0)) | G21: =IF(ISBLANK(pvs_eval!M26), "", IF(pvs_eval!M26 = "Unsafe, Non-Deducible Inference", 0, 1)) | H21: =IF(ISBLANK(pvs_eval!P26), "", IF(pvs_eval!P26 = "No omission", 1, 0)) | I21: =IF(ISBLANK(pvs_eval!T26), "", IF(pvs_eval!T26 = "No extraneous information", 1, 0)) | J21: =IF(ISBLANK(pvs_eval!X26), "", IF(pvs_eval!X26 = "No flow issues", 1, 0))
E22: =IF(ISBLANK(pvs_eval!I27), "", IF(pvs_eval!I27 = "No hallucination", 1, 0)) | F22: =IF(ISBLANK(pvs_eval!L27), "", IF(pvs_eval!L27 = "No clinical inference", 1, 0)) | G22: =IF(ISBLANK(pvs_eval!M27), "", IF(pvs_eval!M27 = "Unsafe, Non-Deducible Inference", 0, 1)) | H22: =IF(ISBLANK(pvs_eval!P27), "", IF(pvs_eval!P27 = "No omission", 1, 0)) | I22: =IF(ISBLANK(pvs_eval!T27), "", IF(pvs_eval!T27 = "No extraneous information", 1, 0)) | J22: =IF(ISBLANK(pvs_eval!X27), "", IF(pvs_eval!X27 = "No flow issues", 1, 0))
E23: =IF(ISBLANK(pvs_eval!I28), "", IF(pvs_eval!I28 = "No hallucination", 1, 0)) | F23: =IF(ISBLANK(pvs_eval!L28), "", IF(pvs_eval!L28 = "No clinical inference", 1, 0)) | G23: =IF(ISBLANK(pvs_eval!M28), "", IF(pvs_eval!M28 = "Unsafe, Non-Deducible Inference", 0, 1)) | H23: =IF(ISBLANK(pvs_eval!P28), "", IF(pvs_eval!P28 = "No omission", 1, 0)) | I23: =IF(ISBLANK(pvs_eval!T28), "", IF(pvs_eval!T28 = "No extraneous information", 1, 0)) | J23: =IF(ISBLANK(pvs_eval!X28), "", IF(pvs_eval!X28 = "No flow issues", 1, 0))
E24: =IF(ISBLANK(pvs_eval!I30), "", IF(pvs_eval!I30 = "No hallucination", 1, 0)) | F24: =IF(ISBLANK(pvs_eval!L30), "", IF(pvs_eval!L30 = "No clinical inference", 1, 0)) | G24: =IF(ISBLANK(pvs_eval!M30), "", IF(pvs_eval!M30 = "Unsafe, Non-Deducible Inference", 0, 1)) | H24: =IF(ISBLANK(pvs_eval!P30), "", IF(pvs_eval!P30 = "No omission", 1, 0)) | I24: =IF(ISBLANK(pvs_eval!T30), "", IF(pvs_eval!T30 = "No extraneous information", 1, 0)) | J24: =IF(ISBLANK(pvs_eval!X30), "", IF(pvs_eval!X30 = "No flow issues", 1, 0))
E25: =IF(ISBLANK(pvs_eval!I31), "", IF(pvs_eval!I31 = "No hallucination", 1, 0)) | F25: =IF(ISBLANK(pvs_eval!L31), "", IF(pvs_eval!L31 = "No clinical inference", 1, 0)) | G25: =IF(ISBLANK(pvs_eval!M31), "", IF(pvs_eval!M31 = "Unsafe, Non-Deducible Inference", 0, 1)) | H25: =IF(ISBLANK(pvs_eval!P31), "", IF(pvs_eval!P31 = "No omission", 1, 0)) | I25: =IF(ISBLANK(pvs_eval!T31), "", IF(pvs_eval!T31 = "No extraneous information", 1, 0)) | J25: =IF(ISBLANK(pvs_eval!X31), "", IF(pvs_eval!X31 = "No flow issues", 1, 0))
E26: =IF(ISBLANK(pvs_eval!I32), "", IF(pvs_eval!I32 = "No hallucination", 1, 0)) | F26: =IF(ISBLANK(pvs_eval!L32), "", IF(pvs_eval!L32 = "No clinical inference", 1, 0)) | G26: =IF(ISBLANK(pvs_eval!M32), "", IF(pvs_eval!M32 = "Unsafe, Non-Deducible Inference", 0, 1)) | H26: =IF(ISBLANK(pvs_eval!P32), "", IF(pvs_eval!P32 = "No omission", 1, 0)) | I26: =IF(ISBLANK(pvs_eval!T32), "", IF(pvs_eval!T32 = "No extraneous information", 1, 0)) | J26: =IF(ISBLANK(pvs_eval!X32), "", IF(pvs_eval!X32 = "No flow issues", 1, 0))
E27: =IF(ISBLANK(pvs_eval!I33), "", IF(pvs_eval!I33 = "No hallucination", 1, 0)) | F27: =IF(ISBLANK(pvs_eval!L33), "", IF(pvs_eval!L33 = "No clinical inference", 1, 0)) | G27: =IF(ISBLANK(pvs_eval!M33), "", IF(pvs_eval!M33 = "Unsafe, Non-Deducible Inference", 0, 1)) | H27: =IF(ISBLANK(pvs_eval!P33), "", IF(pvs_eval!P33 = "No omission", 1, 0)) | I27: =IF(ISBLANK(pvs_eval!T33), "", IF(pvs_eval!T33 = "No extraneous information", 1, 0)) | J27: =IF(ISBLANK(pvs_eval!X33), "", IF(pvs_eval!X33 = "No flow issues", 1, 0))
E28: =IF(ISBLANK(pvs_eval!I35), "", IF(pvs_eval!I35 = "No hallucination", 1, 0)) | F28: =IF(ISBLANK(pvs_eval!L35), "", IF(pvs_eval!L35 = "No clinical inference", 1, 0)) | G28: =IF(ISBLANK(pvs_eval!M35), "", IF(pvs_eval!M35 = "Unsafe, Non-Deducible Inference", 0, 1)) | H28: =IF(ISBLANK(pvs_eval!P35), "", IF(pvs_eval!P35 = "No omission", 1, 0)) | I28: =IF(ISBLANK(pvs_eval!T35), "", IF(pvs_eval!T35 = "No extraneous information", 1, 0)) | J28: =IF(ISBLANK(pvs_eval!X35), "", IF(pvs_eval!X35 = "No flow issues", 1, 0))
E29: =IF(ISBLANK(pvs_eval!I36), "", IF(pvs_eval!I36 = "No hallucination", 1, 0)) | F29: =IF(ISBLANK(pvs_eval!L36), "", IF(pvs_eval!L36 = "No clinical inference", 1, 0)) | G29: =IF(ISBLANK(pvs_eval!M36), "", IF(pvs_eval!M36 = "Unsafe, Non-Deducible Inference", 0, 1)) | H29: =IF(ISBLANK(pvs_eval!P36), "", IF(pvs_eval!P36 = "No omission", 1, 0)) | I29: =IF(ISBLANK(pvs_eval!T36), "", IF(pvs_eval!T36 = "No extraneous information", 1, 0)) | J29: =IF(ISBLANK(pvs_eval!X36), "", IF(pvs_eval!X36 = "No flow issues", 1, 0))
E30: =IF(ISBLANK(pvs_eval!I37), "", IF(pvs_eval!I37 = "No hallucination", 1, 0)) | F30: =IF(ISBLANK(pvs_eval!L37), "", IF(pvs_eval!L37 = "No clinical inference", 1, 0)) | G30: =IF(ISBLANK(pvs_eval!M37), "", IF(pvs_eval!M37 = "Unsafe, Non-Deducible Inference", 0, 1)) | H30: =IF(ISBLANK(pvs_eval!P37), "", IF(pvs_eval!P37 = "No omission", 1, 0)) | I30: =IF(ISBLANK(pvs_eval!T37), "", IF(pvs_eval!T37 = "No extraneous information", 1, 0)) | J30: =IF(ISBLANK(pvs_eval!X37), "", IF(pvs_eval!X37 = "No flow issues", 1, 0))
E31: =IF(ISBLANK(pvs_eval!I38), "", IF(pvs_eval!I38 = "No hallucination", 1, 0)) | F31: =IF(ISBLANK(pvs_eval!L38), "", IF(pvs_eval!L38 = "No clinical inference", 1, 0)) | G31: =IF(ISBLANK(pvs_eval!M38), "", IF(pvs_eval!M38 = "Unsafe, Non-Deducible Inference", 0, 1)) | H31: =IF(ISBLANK(pvs_eval!P38), "", IF(pvs_eval!P38 = "No omission", 1, 0)) | I31: =IF(ISBLANK(pvs_eval!T38), "", IF(pvs_eval!T38 = "No extraneous information", 1, 0)) | J31: =IF(ISBLANK(pvs_eval!X38), "", IF(pvs_eval!X38 = "No flow issues", 1, 0))
E32: =IF(ISBLANK(pvs_eval!I40), "", IF(pvs_eval!I40 = "No hallucination", 1, 0)) | F32: =IF(ISBLANK(pvs_eval!L40), "", IF(pvs_eval!L40 = "No clinical inference", 1, 0)) | G32: =IF(ISBLANK(pvs_eval!M40), "", IF(pvs_eval!M40 = "Unsafe, Non-Deducible Inference", 0, 1)) | H32: =IF(ISBLANK(pvs_eval!P40), "", IF(pvs_eval!P40 = "No omission", 1, 0)) | I32: =IF(ISBLANK(pvs_eval!T40), "", IF(pvs_eval!T40 = "No extraneous information", 1, 0)) | J32: =IF(ISBLANK(pvs_eval!X40), "", IF(pvs_eval!X40 = "No flow issues", 1, 0))
E33: =IF(ISBLANK(pvs_eval!I41), "", IF(pvs_eval!I41 = "No hallucination", 1, 0)) | F33: =IF(ISBLANK(pvs_eval!L41), "", IF(pvs_eval!L41 = "No clinical inference", 1, 0)) | G33: =IF(ISBLANK(pvs_eval!M41), "", IF(pvs_eval!M41 = "Unsafe, Non-Deducible Inference", 0, 1)) | H33: =IF(ISBLANK(pvs_eval!P41), "", IF(pvs_eval!P41 = "No omission", 1, 0)) | I33: =IF(ISBLANK(pvs_eval!T41), "", IF(pvs_eval!T41 = "No extraneous information", 1, 0)) | J33: =IF(ISBLANK(pvs_eval!X41), "", IF(pvs_eval!X41 = "No flow issues", 1, 0))
E34: =IF(ISBLANK(pvs_eval!I42), "", IF(pvs_eval!I42 = "No hallucination", 1, 0)) | F34: =IF(ISBLANK(pvs_eval!L42), "", IF(pvs_eval!L42 = "No clinical inference", 1, 0)) | G34: =IF(ISBLANK(pvs_eval!M42), "", IF(pvs_eval!M42 = "Unsafe, Non-Deducible Inference", 0, 1)) | H34: =IF(ISBLANK(pvs_eval!P42), "", IF(pvs_eval!P42 = "No omission", 1, 0)) | I34: =IF(ISBLANK(pvs_eval!T42), "", IF(pvs_eval!T42 = "No extraneous information", 1, 0)) | J34: =IF(ISBLANK(pvs_eval!X42), "", IF(pvs_eval!X42 = "No flow issues", 1, 0))
E35: =IF(ISBLANK(pvs_eval!I43), "", IF(pvs_eval!I43 = "No hallucination", 1, 0)) | F35: =IF(ISBLANK(pvs_eval!L43), "", IF(pvs_eval!L43 = "No clinical inference", 1, 0)) | G35: =IF(ISBLANK(pvs_eval!M43), "", IF(pvs_eval!M43 = "Unsafe, Non-Deducible Inference", 0, 1)) | H35: =IF(ISBLANK(pvs_eval!P43), "", IF(pvs_eval!P43 = "No omission", 1, 0)) | I35: =IF(ISBLANK(pvs_eval!T43), "", IF(pvs_eval!T43 = "No extraneous information", 1, 0)) | J35: =IF(ISBLANK(pvs_eval!X43), "", IF(pvs_eval!X43 = "No flow issues", 1, 0))
E36: =IF(ISBLANK(pvs_eval!I45), "", IF(pvs_eval!I45 = "No hallucination", 1, 0)) | F36: =IF(ISBLANK(pvs_eval!L45), "", IF(pvs_eval!L45 = "No clinical inference", 1, 0)) | G36: =IF(ISBLANK(pvs_eval!M45), "", IF(pvs_eval!M45 = "Unsafe, Non-Deducible Inference", 0, 1)) | H36: =IF(ISBLANK(pvs_eval!P45), "", IF(pvs_eval!P45 = "No omission", 1, 0)) | I36: =IF(ISBLANK(pvs_eval!T45), "", IF(pvs_eval!T45 = "No extraneous information", 1, 0)) | J36: =IF(ISBLANK(pvs_eval!X45), "", IF(pvs_eval!X45 = "No flow issues", 1, 0))
E37: =IF(ISBLANK(pvs_eval!I46), "", IF(pvs_eval!I46 = "No hallucination", 1, 0)) | F37: =IF(ISBLANK(pvs_eval!L46), "", IF(pvs_eval!L46 = "No clinical inference", 1, 0)) | G37: =IF(ISBLANK(pvs_eval!M46), "", IF(pvs_eval!M46 = "Unsafe, Non-Deducible Inference", 0, 1)) | H37: =IF(ISBLANK(pvs_eval!P46), "", IF(pvs_eval!P46 = "No omission", 1, 0)) | I37: =IF(ISBLANK(pvs_eval!T46), "", IF(pvs_eval!T46 = "No extraneous information", 1, 0)) | J37: =IF(ISBLANK(pvs_eval!X46), "", IF(pvs_eval!X46 = "No flow issues", 1, 0))
E38: =IF(ISBLANK(pvs_eval!I47), "", IF(pvs_eval!I47 = "No hallucination", 1, 0)) | F38: =IF(ISBLANK(pvs_eval!L47), "", IF(pvs_eval!L47 = "No clinical inference", 1, 0)) | G38: =IF(ISBLANK(pvs_eval!M47), "", IF(pvs_eval!M47 = "Unsafe, Non-Deducible Inference", 0, 1)) | H38: =IF(ISBLANK(pvs_eval!P47), "", IF(pvs_eval!P47 = "No omission", 1, 0)) | I38: =IF(ISBLANK(pvs_eval!T47), "", IF(pvs_eval!T47 = "No extraneous information", 1, 0)) | J38: =IF(ISBLANK(pvs_eval!X47), "", IF(pvs_eval!X47 = "No flow issues", 1, 0))
E39: =IF(ISBLANK(pvs_eval!I48), "", IF(pvs_eval!I48 = "No hallucination", 1, 0)) | F39: =IF(ISBLANK(pvs_eval!L48), "", IF(pvs_eval!L48 = "No clinical inference", 1, 0)) | G39: =IF(ISBLANK(pvs_eval!M48), "", IF(pvs_eval!M48 = "Unsafe, Non-Deducible Inference", 0, 1)) | H39: =IF(ISBLANK(pvs_eval!P48), "", IF(pvs_eval!P48 = "No omission", 1, 0)) | I39: =IF(ISBLANK(pvs_eval!T48), "", IF(pvs_eval!T48 = "No extraneous information", 1, 0)) | J39: =IF(ISBLANK(pvs_eval!X48), "", IF(pvs_eval!X48 = "No flow issues", 1, 0))
E40: =IF(ISBLANK(pvs_eval!I50), "", IF(pvs_eval!I50 = "No hallucination", 1, 0)) | F40: =IF(ISBLANK(pvs_eval!L50), "", IF(pvs_eval!L50 = "No clinical inference", 1, 0)) | G40: =IF(ISBLANK(pvs_eval!M50), "", IF(pvs_eval!M50 = "Unsafe, Non-Deducible Inference", 0, 1)) | H40: =IF(ISBLANK(pvs_eval!P50), "", IF(pvs_eval!P50 = "No omission", 1, 0)) | I40: =IF(ISBLANK(pvs_eval!T50), "", IF(pvs_eval!T50 = "No extraneous information", 1, 0)) | J40: =IF(ISBLANK(pvs_eval!X50), "", IF(pvs_eval!X50 = "No flow issues", 1, 0))
...
